Workbook

Sheet Read Me
A1: TourStar — Sample P&L (36 months)
A2: Illustrative model for planning and investor conversations. Not a forecast or financial advice.
A4: How to use
A5: 1. Go to the Assumptions tab and pick a scenario in the yellow cell (Low, Base or High).
A6: 2. Every blue number on Assumptions is an input you can change; Monthly and Annual recalculate.
A7: 3. Monthly has the month-by-month users, revenue and costs; Annual rolls it up by year.
A9: Color key
A10: Blue text = input you can change · Black = formula · Green = pulled from another tab · Yellow fill = scenario switch / key input
A12: How users are modeled
A13: Monthly active users (MAU) = this month's new installs + share of last month's new installs who come back + veteran players who stay.
A14: New installs = waitlist conversion at launch + organic + paid marketing (budget ÷ cost per install) + artist-partner launch bumps.
A15: Accounts (signups) = installs × account signup rate; VIP and spenders are shares of MAU.
... A23: Current waitlist: 1 signup (live database, Oct 30 2026) — the waitlist-at-launch numbers are targets, not actuals.

Sheet Assumptions
A1: Assumptions
A3: Scenario | B3: Base | C3: ← pick Low, Base or High
A4: Launch month | B4: 46388 | C4: Month 1 of the model (App Store launch)
A6: Assumption | B6: Low | C6: Base | D6: High | E6: Active | F6: Unit | G6: Note / source
A7: Installs and signups
A8: Waitlist size at launch | B8: 5000 | C8: 15000 | D8: 40000 | E8: =INDEX(B8:D8,MATCH($B$3,$B$6:$D$6,0)) -> 15000 | F8: people | G8: Target to build before launch (today: 1)
A9: Waitlist → install at launch | B9: 0.3 | C9: 0.4 | D9: 0.5 | E9: =INDEX(B9:D9,MATCH($B$3,$B$6:$D$6,0)) -> 0.4 | F9: % | G9: Share of waitlist who install in month 1
A10: Organic installs, month 1 | B10: 2000 | C10: 5000 | D10: 12000 | E10: =INDEX(B10:D10,MATCH($B$3,$B$6:$D$6,0)) -> 5000 | F10: installs | G10: App Store search, word of mouth, press
A11: Organic install growth per month | B11: 0.03 | C11: 0.06 | D11: 0.1 | E11: =INDEX(B11:D11,MATCH($B$3,$B$6:$D$6,0)) -> 0.06 | F11: % | G11: Compounds monthly
A12: Paid marketing per month, Year 1 | B12: 3000 | C12: 10000 | D12: 25000 | E12: =INDEX(B12:D12,MATCH($B$3,$B$6:$D$6,0)) -> 10000 | F12: $ | G12: User acquisition budget
A13: Paid marketing per month, Year 2 | B13: 5000 | C13: 25000 | D13: 75000 | E13: =INDEX(B13:D13,MATCH($B$3,$B$6:$D$6,0)) -> 25000 | F13: $
A14: Paid marketing per month, Year 3 | B14: 8000 | C14: 50000 | D14: 150000 | E14: =INDEX(B14:D14,MATCH($B$3,$B$6:$D$6,0)) -> 50000 | F14: $
A15: Blended cost per install | B15: 3.5 | C15: 2.75 | D15: 2.25 | E15: =INDEX(B15:D15,MATCH($B$3,$B$6:$D$6,0)) -> 2.75 | F15: $ | G15: iOS US casual games; see Read Me
A16: Artist partner launch every N months | B16: 6 | C16: 3 | D16: 2 | E16: =INDEX(B16:D16,MATCH($B$3,$B$6:$D$6,0)) -> 3 | F16: months | G16: First launch in month 3
A17: Length of each artist partnership | B17: 12 | C17: 12 | D17: 12 | E17: =INDEX(B17:D17,MATCH($B$3,$B$6:$D$6,0)) -> 12 | F17: months | G17: Licensing and giveaways stop when it ends
A18: Installs per artist partner launch | B18: 5000 | C18: 15000 | D18: 40000 | E18: =INDEX(B18:D18,MATCH($B$3,$B$6:$D$6,0)) -> 15000 | F18: installs | G18: Artist socials, presale and merch cross-promo
A19: Installs who create an account | B19: 0.3 | C19: 0.4 | D19: 0.5 | E19: =INDEX(B19:D19,MATCH($B$3,$B$6:$D$6,0)) -> 0.4 | F19: % | G19: Apple sign-in / email; rest play as guests
A20: Retention
A21: New players still active the next month | B21: 0.12 | C21: 0.18 | D21: 0.24 | E21: =INDEX(B21:D21,MATCH($B$3,$B$6:$D$6,0)) -> 0.18 | F21: % | G21: ≈ day-30 retention
A22: Veteran players retained each month | B22: 0.65 | C22: 0.75 | D22: 0.82 | E22: =INDEX(B22:D22,MATCH($B$3,$B$6:$D$6,0)) -> 0.75 | F22: % | G22: Players past their first month
A23: Monetization (gross, before store fees)
A24: VIP subscribers (share of MAU) | B24: 0.008 | C24: 0.015 | D24: 0.025 | E24: =INDEX(B24:D24,MATCH($B$3,$B$6:$D$6,0)) -> 0.015 | F24: % | G24: $4.99/mo or $39.99/yr
A25: VIP blended revenue per subscriber | B25: 4 | C25: 4 | D25: 4 | E25: =INDEX(B25:D25,MATCH($B$3,$B$6:$D$6,0)) -> 4 | F25: $/mo | G25: Mix of monthly and yearly plans
A26: In-app spenders (share of MAU, excl. VIP) | B26: 0.015 | C26: 0.025 | D26: 0.035 | E26: =INDEX(B26:D26,MATCH($B$3,$B$6:$D$6,0)) -> 0.025 | F26: % | G26: Gold Records, AI song packs, cash packs, artist packs
A27: Average spend per spender | B27: 6 | C27: 8 | D27: 11 | E27: =INDEX(B27:D27,MATCH($B$3,$B$6:$D$6,0)) -> 8 | F27: $/mo
A28: Share of in-app spend on artist packs | B28: 0.2 | C28: 0.3 | D28: 0.4 | E28: =INDEX(B28:D28,MATCH($B$3,$B$6:$D$6,0)) -> 0.3 | F28: % | G28: Drives artist revenue share
A29: Merch orders (share of MAU per month) | B29: 0.001 | C29: 0.0025 | D29: 0.004 | E29: =INDEX(B29:D29,MATCH($B$3,$B$6:$D$6,0)) -> 0.0025 | F29: % | G29: Shopify store, in-game unlocks
A30: Average merch order | B30: 30 | C30: 35 | D30: 40 | E30: =INDEX(B30:D30,MATCH($B$3,$B$6:$D$6,0)) -> 35 | F30: $
A31: Brand & venue sponsorships per month | B31: 0 | C31: 5000 | D31: 15000 | E31: =INDEX(B31:D31,MATCH($B$3,$B$6:$D$6,0)) -> 5000 | F31: $ | G31: Starts month 7, grows 5%/month
A32: Costs
A33: App Store / Google Play fee | B33: 0.15 | C33: 0.15 | D33: 0.15 | E33: =INDEX(B33:D33,MATCH($B$3,$B$6:$D$6,0)) -> 0.15 | F33: % | G33: Small Business Program rate under $1M/yr
A34: RevenueCat free tier (monthly revenue) | B34: 2500 | C34: 2500 | D34: 2500 | E34: =INDEX(B34:D34,MATCH($B$3,$B$6:$D$6,0)) -> 2500 | F34: $
A35: RevenueCat fee above free tier | B35: 0.01 | C35: 0.01 | D35: 0.01 | E35: =INDEX(B35:D35,MATCH($B$3,$B$6:$D$6,0)) -> 0.01 | F35: %
A36: Artist revenue share on artist packs | B36: 0.3 | C36: 0.3 | D36: 0.3 | E36: =INDEX(B36:D36,MATCH($B$3,$B$6:$D$6,0)) -> 0.3 | F36: % | G36: From the pitch deck deal shape
A37: Music licensing per active partnership | B37: 1500 | C37: 1000 | D37: 1000 | E37: =INDEX(B37:D37,MATCH($B$3,$B$6:$D$6,0)) -> 1000 | F37: $/mo | G37: Publisher sync for game-style songs
A38: Tour ticket & VIP giveaways per active partnership | B38: 2000 | C38: 1500 | D38: 1500 | E38: =INDEX(B38:D38,MATCH($B$3,$B$6:$D$6,0)) -> 1500 | F38: $/mo | G38: Free tickets every show, VIP packages
A39: Player prizes, base | B39: 1500 | C39: 2000 | D39: 3000 | E39: =INDEX(B39:D39,MATCH($B$3,$B$6:$D$6,0)) -> 2000 | F39: $/mo | G39: Rewards store fulfilled by Please & Thank You
A40: Player prizes per MAU | B40: 0.05 | C40: 0.05 | D40: 0.05 | E40: =INDEX(B40:D40,MATCH($B$3,$B$6:$D$6,0)) -> 0.05 | F40: $/MAU
A41: Merch cost of goods + fulfillment | B41: 0.6 | C41: 0.55 | D41: 0.5 | E41: =INDEX(B41:D41,MATCH($B$3,$B$6:$D$6,0)) -> 0.55 | F41: % of sales
A42: AI songs, voice and press per MAU | B42: 0.05 | C42: 0.04 | D42: 0.04 | E42: =INDEX(B42:D42,MATCH($B$3,$B$6:$D$6,0)) -> 0.04 | F42: $/MAU | G42: ElevenLabs + Claude API, with daily caps
...

Sheet Annual
A1: Annual summary
A2: ="Scenario: "&Assumptions!$B$3 -> Scenario: Base
A4: Line item | B4: Year 1 | C4: Year 2 | D4: Year 3 | E4: 3-year total
A5: USERS
A6: New installs | B6: =SUM(Monthly!C13:N13) -> 193986.07 | C6: =SUM(Monthly!O13:Z13) -> 338819.09 | D6: =SUM(Monthly!AA13:AL13) -> 619708.26 | E6: =SUM(B6:D6) -> 1152513.4
A7: Total accounts (end of year) | B7: =Monthly!N16 -> 77594.428 | C7: =Monthly!Z16 -> 213122.06 | D7: =Monthly!AL16 -> 461005.37 | E7: =D7 -> 461005.37
A8: Monthly active users (end of year) | B8: =Monthly!N17 -> 38514.626 | C8: =Monthly!Z17 -> 63274.157 | D8: =Monthly!AL17 -> 109362.56 | E8: =D8 -> 109362.56
A9: VIP subscribers (end of year) | B9: =Monthly!N18 -> 577.71939 | C9: =Monthly!Z18 -> 949.11236 | D9: =Monthly!AL18 -> 1640.4384 | E9: =D9 -> 1640.4384
A10: Active artist partnerships (end of year) | B10: =Monthly!N20 -> 4 | C10: =Monthly!Z20 -> 4 | D10: =Monthly!AL20 -> 4 | E10: =D10 -> 4
A11: REVENUE
A12: VIP subscriptions | B12: =SUM(Monthly!C22:N22) -> 16934.62 | C12: =SUM(Monthly!O22:Z22) -> 32569.869 | D12: =SUM(Monthly!AA22:AL22) -> 59546.191 | E12: =SUM(B12:D12) -> 109050.68
A13: In-app purchases | B13: =SUM(Monthly!C23:N23) -> 56448.735 | C13: =SUM(Monthly!O23:Z23) -> 108566.23 | D13: =SUM(Monthly!AA23:AL23) -> 198487.3 | E13: =SUM(B13:D13) -> 363502.27
A14: Merch sales | B14: =SUM(Monthly!C24:N24) -> 24696.321 | C14: =SUM(Monthly!O24:Z24) -> 47497.725 | D14: =SUM(Monthly!AA24:AL24) -> 86838.196 | E14: =SUM(B14:D14) -> 159032.24
A15: Brand & venue sponsorships | B15: =SUM(Monthly!C25:N25) -> 34009.564 | C15: =SUM(Monthly!O25:Z25) -> 106652.36 | D15: =SUM(Monthly!AA25:AL25) -> 191532.31 | E15: =SUM(B15:D15) -> 332194.24
A16: Total revenue | B16: =SUM(Monthly!C26:N26) -> 132089.24 | C16: =SUM(Monthly!O26:Z26) -> 295286.18 | D16: =SUM(Monthly!AA26:AL26) -> 536404.01 | E16: =SUM(B16:D16) -> 963779.43
A17: COSTS
A18: Cost of revenue | B18: =SUM(Monthly!C37:N37) -> 139002.52 | C18: =SUM(Monthly!O37:Z37) -> 256908.29 | D18: =SUM(Monthly!AA37:AL37) -> 348189.42 | E18: =SUM(B18:D18) -> 744100.24
A19: Gross profit | B19: =SUM(Monthly!C38:N38) -> -6913.2812 | C19: =SUM(Monthly!O38:Z38) -> 38377.889 | D19: =SUM(Monthly!AA38:AL38) -> 188214.58 | E19: =SUM(B19:D19) -> 219679.19
A20: Gross margin | B20: =IFERROR(B19/B16,0) -> -0.052337959 | C20: =IFERROR(C19/C16,0) -> 0.12996846 | D20: =IFERROR(D19/D16,0) -> 0.35088213 | E20: =IFERROR(E19/E16,0) -> 0.22793513
A21: Paid marketing | B21: =SUM(Monthly!C41:N41) -> 120000 | C21: =SUM(Monthly!O41:Z41) -> 300000 | D21: =SUM(Monthly!AA41:AL41) -> 600000 | E21: =SUM(B21:D21) -> 1020000
A22: Team & contractors | B22: =SUM(Monthly!C42:N42) -> 300000 | C22: =SUM(Monthly!O42:Z42) -> 540000 | D22: =SUM(Monthly!AA42:AL42) -> 840000 | E22: =SUM(B22:D22) -> 1680000
A23: Support, legal, G&A | B23: =SUM(Monthly!C43:N43)+SUM(Monthly!C44:N44) -> 53644.873 | C23: =SUM(Monthly!O43:Z43)+SUM(Monthly!O44:Z44) -> 58856.623 | D23: =SUM(Monthly!AA43:AL43)+SUM(Monthly!AA44:AL44) -> 67848.73 | E23: =SUM(B23:D23) -> 180350.23
A24: Total operating expenses | B24: =SUM(Monthly!C45:N45) -> 473644.87 | C24: =SUM(Monthly!O45:Z45) -> 898856.62 | D24: =SUM(Monthly!AA45:AL45) -> 1507848.7 | E24: =SUM(B24:D24) -> 2880350.2
A25: BOTTOM LINE
A26: EBITDA (profit / loss) | B26: =SUM(Monthly!C47:N47) -> -480558.15 | C26: =SUM(Monthly!O47:Z47) -> -860478.73 | D26: =SUM(Monthly!AA47:AL47) -> -1319634.1 | E26: =SUM(B26:D26) -> -2660671
A27: Cash balance (end of year) | B27: =Monthly!N48 -> 19441.845 | C27: =Monthly!Z48 -> -841036.89 | D27: =Monthly!AL48 -> -2160671 | E27: =D27 -> -2160671
A29: Lowest cash point (36 months) | B29: =MIN(Monthly!C48:AL48) -> -2160671
A30: First month with a monthly profit | B30: =IFERROR(INDEX(Monthly!C4:AL4,MATCH(TRUE(),INDEX(Monthly!C47:AL47>0,0),0)),"Not within 36 months") -> Not within 36 months

Sheet Monthly
A1: Monthly model
A2: ="Scenario: "&Assumptions!$B$3 -> Scenario: Base
A3: Month # | C3: 1 | D3: 2 | E3: 3 | F3: 4 | G3: 5 | H3: 6 | I3: 7 | J3: 8 | K3: 9 | L3: 10 | M3: 11 | N3: 12 | O3: 13 | P3: 14 | Q3: 15 | R3: 16 | S3: 17 | T3: 18 | U3: 19 | V3: 20 | W3: 21 | X3: 22 | Y3: 23 | Z3: 24 | AA3: 25 | AB3: 26 | AC3: 27 | AD3: 28 | AE3: 29 | AF3: 30 | AG3: 31 | AH3: 32 | AI3: 33 | AJ3: 34 | AK3: 35 | AL3: 36
A4: Line item | B4: Notes | C4: =EDATE(Assumptions!$B$4,0) -> 46388 | D4: =EDATE(Assumptions!$B$4,1) -> 46419 | E4: =EDATE(Assumptions!$B$4,2) -> 46447 | F4: =EDATE(Assumptions!$B$4,3) -> 46478 | G4: =EDATE(Assumptions!$B$4,4) -> 46508 | H4: =EDATE(Assumptions!$B$4,5) -> 46539 | I4: =EDATE(Assumptions!$B$4,6) -> 46569 | J4: =EDATE(Assumptions!$B$4,7) -> 46600 | K4: =EDATE(Assumptions!$B$4,8) -> 46631 | L4: =EDATE(Assumptions!$B$4,9) -> 46661 | M4: =EDATE(Assumptions!$B$4,10) -> 46692 | N4: =EDATE(Assumptions!$B$4,11) -> 46722 | O4: =EDATE(Assumptions!$B$4,12) -> 46753 | P4: =EDATE(Assumptions!$B$4,13) -> 46784 | Q4: =EDATE(Assumptions!$B$4,14) -> 46813 | R4: =EDATE(Assumptions!$B$4,15) -> 46844 | S4: =EDATE(Assumptions!$B$4,16) -> 46874 | T4: =EDATE(Assumptions!$B$4,17) -> 46905 | U4: =EDATE(Assumptions!$B$4,18) -> 46935 | V4: =EDATE(Assumptions!$B$4,19) -> 46966 | W4: =EDATE(Assumptions!$B$4,20) -> 46997 | X4: =EDATE(Assumptions!$B$4,21) -> 47027 | Y4: =EDATE(Assumptions!$B$4,22) -> 47058 | Z4: =EDATE(Assumptions!$B$4,23) -> 47088 | AA4: =EDATE(Assumptions!$B$4,24) -> 47119 | AB4: =EDATE(Assumptions!$B$4,25) -> 47150 | AC4: =EDATE(Assumptions!$B$4,26) -> 47178 | AD4: =EDATE(Assumptions!$B$4,27) -> 47209 | AE4: =EDATE(Assumptions!$B$4,28) -> 47239 | AF4: =EDATE(Assumptions!$B$4,29) -> 47270 | AG4: =EDATE(Assumptions!$B$4,30) -> 47300 | AH4: =EDATE(Assumptions!$B$4,31) -> 47331 | AI4: =EDATE(Assumptions!$B$4,32) -> 47362 | AJ4: =EDATE(Assumptions!$B$4,33) -> 47392 | AK4: =EDATE(Assumptions!$B$4,34) -> 47423 | AL4: =EDATE(Assumptions!$B$4,35) -> 47453
A5: Year | C5: =INT((0)/12)+1 -> 1 | D5: =INT((1)/12)+1 -> 1 | E5: =INT((2)/12)+1 -> 1 | F5: =INT((3)/12)+1 -> 1 | G5: =INT((4)/12)+1 -> 1 | H5: =INT((5)/12)+1 -> 1 | I5: =INT((6)/12)+1 -> 1 | J5: =INT((7)/12)+1 -> 1 | K5: =INT((8)/12)+1 -> 1 | L5: =INT((9)/12)+1 -> 1 | M5: =INT((10)/12)+1 -> 1 | N5: =INT((11)/12)+1 -> 1 | O5: =INT((12)/12)+1 -> 2 | P5: =INT((13)/12)+1 -> 2 | Q5: =INT((14)/12)+1 -> 2 | R5: =INT((15)/12)+1 -> 2 | S5: =INT((16)/12)+1 -> 2 | T5: =INT((17)/12)+1 -> 2 | U5: =INT((18)/12)+1 -> 2 | V5: =INT((19)/12)+1 -> 2 | W5: =INT((20)/12)+1 -> 2 | X5: =INT((21)/12)+1 -> 2 | Y5: =INT((22)/12)+1 -> 2 | Z5: =INT((23)/12)+1 -> 2 | AA5: =INT((24)/12)+1 -> 3 | AB5: =INT((25)/12)+1 -> 3 | AC5: =INT((26)/12)+1 -> 3 | AD5: =INT((27)/12)+1 -> 3 | AE5: =INT((28)/12)+1 -> 3 | AF5: =INT((29)/12)+1 -> 3 | AG5: =INT((30)/12)+1 -> 3 | AH5: =INT((31)/12)+1 -> 3 | AI5: =INT((32)/12)+1 -> 3 | AJ5: =INT((33)/12)+1 -> 3 | AK5: =INT((34)/12)+1 -> 3 | AL5: =INT((35)/12)+1 -> 3
A6: USERS
A7: Waitlist installs (launch) | C7: =IF(C$3=1,Assumptions!$E$8*Assumptions!$E$9,0) -> 6000 | D7: =IF(D$3=1,Assumptions!$E$8*Assumptions!$E$9,0) -> 0 | E7: =IF(E$3=1,Assumptions!$E$8*Assumptions!$E$9,0) -> 0 | F7: =IF(F$3=1,Assumptions!$E$8*Assumptions!$E$9,0) -> 0 | G7: =IF(G$3=1,Assumptions!$E$8*Assumptions!$E$9,0) -> 0 | H7: =IF(H$3=1,Assumptions!$E$8*Assumptions!$E$9,0) -> 0 | I7: =IF(I$3=1,Assumptions!$E$8*Assumptions!$E$9,0) -> 0 | J7: =IF(J$3=1,Assumptions!$E$8*Assumptions!$E$9,0) -> 0 | ... AL7: =IF(AL$3=1,Assumptions!$E$8*Assumptions!$E$9,0) -> 0
A8: Organic installs | C8: =Assumptions!$E$10*(1+Assumptions!$E$11)^(C$3-1) -> 5000 | D8: =Assumptions!$E$10*(1+Assumptions!$E$11)^(D$3-1) -> 5300 | E8: =Assumptions!$E$10*(1+Assumptions!$E$11)^(E$3-1) -> 5618 | F8: =Assumptions!$E$10*(1+Assumptions!$E$11)^(F$3-1) -> 5955.08 | G8: =Assumptions!$E$10*(1+Assumptions!$E$11)^(G$3-1) -> 6312.3848 | H8: =Assumptions!$E$10*(1+Assumptions!$E$11)^(H$3-1) -> 6691.1279 | I8: =Assumptions!$E$10*(1+Assumptions!$E$11)^(I$3-1) -> 7092.5956 | J8: =Assumptions!$E$10*(1+Assumptions!$E$11)^(J$3-1) -> 7518.1513 | ... AL8: =Assumptions!$E$10*(1+Assumptions!$E$11)^(AL$3-1) -> 38430.434
A9: Paid marketing spend | C9: =CHOOSE(MIN(C$5,3),Assumptions!$E$12,Assumptions!$E$13,Assumptions!$E$14) -> 10000 | D9: =CHOOSE(MIN(D$5,3),Assumptions!$E$12,Assumptions!$E$13,Assumptions!$E$14) -> 10000 | E9: =CHOOSE(MIN(E$5,3),Assumptions!$E$12,Assumptions!$E$13,Assumptions!$E$14) -> 10000 | F9: =CHOOSE(MIN(F$5,3),Assumptions!$E$12,Assumptions!$E$13,Assumptions!$E$14) -> 10000 | G9: =CHOOSE(MIN(G$5,3),Assumptions!$E$12,Assumptions!$E$13,Assumptions!$E$14) -> 10000 | H9: =CHOOSE(MIN(H$5,3),Assumptions!$E$12,Assumptions!$E$13,Assumptions!$E$14) -> 10000 | I9: =CHOOSE(MIN(I$5,3),Assumptions!$E$12,Assumptions!$E$13,Assumptions!$E$14) -> 10000 | J9: =CHOOSE(MIN(J$5,3),Assumptions!$E$12,Assumptions!$E$13,Assumptions!$E$14) -> 10000 | ... AL9: =CHOOSE(MIN(AL$5,3),Assumptions!$E$12,Assumptions!$E$13,Assumptions!$E$14) -> 50000
A10: Paid installs | C10: =IFERROR(C9/Assumptions!$E$15,0) -> 3636.3636 | D10: =IFERROR(D9/Assumptions!$E$15,0) -> 3636.3636 | E10: =IFERROR(E9/Assumptions!$E$15,0) -> 3636.3636 | F10: =IFERROR(F9/Assumptions!$E$15,0) -> 3636.3636 | G10: =IFERROR(G9/Assumptions!$E$15,0) -> 3636.3636 | H10: =IFERROR(H9/Assumptions!$E$15,0) -> 3636.3636 | I10: =IFERROR(I9/Assumptions!$E$15,0) -> 3636.3636 | J10: =IFERROR(J9/Assumptions!$E$15,0) -> 3636.3636 | ... AL10: =IFERROR(AL9/Assumptions!$E$15,0) -> 18181.818
A11: Artist partner launches | C11: =IF(AND(C$3>=3,MOD(C$3-3,Assumptions!$E$16)=0),1,0) -> 0 | D11: =IF(AND(D$3>=3,MOD(D$3-3,Assumptions!$E$16)=0),1,0) -> 0 | E11: =IF(AND(E$3>=3,MOD(E$3-3,Assumptions!$E$16)=0),1,0) -> 1 | F11: =IF(AND(F$3>=3,MOD(F$3-3,Assumptions!$E$16)=0),1,0) -> 0 | G11: =IF(AND(G$3>=3,MOD(G$3-3,Assumptions!$E$16)=0),1,0) -> 0 | H11: =IF(AND(H$3>=3,MOD(H$3-3,Assumptions!$E$16)=0),1,0) -> 1 | I11: =IF(AND(I$3>=3,MOD(I$3-3,Assumptions!$E$16)=0),1,0) -> 0 | J11: =IF(AND(J$3>=3,MOD(J$3-3,Assumptions!$E$16)=0),1,0) -> 0 | ... AL11: =IF(AND(AL$3>=3,MOD(AL$3-3,Assumptions!$E$16)=0),1,0) -> 1
A12: Artist partner installs | C12: =C11*Assumptions!$E$18 -> 0 | D12: =D11*Assumptions!$E$18 -> 0 | E12: =E11*Assumptions!$E$18 -> 15000 | F12: =F11*Assumptions!$E$18 -> 0 | G12: =G11*Assumptions!$E$18 -> 0 | H12: =H11*Assumptions!$E$18 -> 15000 | I12: =I11*Assumptions!$E$18 -> 0 | J12: =J11*Assumptions!$E$18 -> 0 | ... AL12: =AL11*Assumptions!$E$18 -> 15000
A13: Total new installs | C13: =C7+C8+C10+C12 -> 14636.364 | D13: =D7+D8+D10+D12 -> 8936.3636 | E13: =E7+E8+E10+E12 -> 24254.364 | F13: =F7+F8+F10+F12 -> 9591.4436 | G13: =G7+G8+G10+G12 -> 9948.7484 | H13: =H7+H8+H10+H12 -> 25327.492 | I13: =I7+I8+I10+I12 -> 10728.959 | J13: =J7+J8+J10+J12 -> 11154.515 | ... AL13: =AL7+AL8+AL10+AL12 -> 71612.252
A14: Cumulative installs | C14: =C13 -> 14636.364 | D14: =C14+D13 -> 23572.727 | E14: =D14+E13 -> 47827.091 | F14: =E14+F13 -> 57418.535 | G14: =F14+G13 -> 67367.283 | H14: =G14+H13 -> 92694.775 | I14: =H14+I13 -> 103423.73 | J14: =I14+J13 -> 114578.25 | K14: =J14+K13 -> 141183.85 | ... AL14: =AK14+AL13 -> 1152513.4
A15: New accounts (signups) | C15: =C13*Assumptions!$E$19 -> 5854.5455 | D15: =D13*Assumptions!$E$19 -> 3574.5455 | E15: =E13*Assumptions!$E$19 -> 9701.7455 | F15: =F13*Assumptions!$E$19 -> 3836.5775 | G15: =G13*Assumptions!$E$19 -> 3979.4994 | H15: =H13*Assumptions!$E$19 -> 10130.997 | I15: =I13*Assumptions!$E$19 -> 4291.5837 | J15: =J13*Assumptions!$E$19 -> 4461.806 | ... AL15: =AL13*Assumptions!$E$19 -> 28644.901
A16: Total accounts | C16: =C15 -> 5854.5455 | D16: =C16+D15 -> 9429.0909 | E16: =D16+E15 -> 19130.836 | F16: =E16+F15 -> 22967.414 | G16: =F16+G15 -> 26946.913 | H16: =G16+H15 -> 37077.91 | I16: =H16+I15 -> 41369.493 | J16: =I16+J15 -> 45831.299 | K16: =J16+K15 -> 56473.541 | ... AL16: =AK16+AL15 -> 461005.37
A17: Monthly active users (MAU) | C17: =C13 -> 14636.364 | D17: =D13+C13*Assumptions!$E$21+MAX(0,C17-C13)*Assumptions!$E$22 -> 11570.909 | E17: =E13+D13*Assumptions!$E$21+MAX(0,D17-D13)*Assumptions!$E$22 -> 27838.818 | F17: =F13+E13*Assumptions!$E$21+MAX(0,E17-E13)*Assumptions!$E$22 -> 16645.57 | G17: =G13+F13*Assumptions!$E$21+MAX(0,F17-F13)*Assumptions!$E$22 -> 16965.803 | H17: =H13+G13*Assumptions!$E$21+MAX(0,G17-G13)*Assumptions!$E$22 -> 32381.057 | I17: =I13+H13*Assumptions!$E$21+MAX(0,H17-H13)*Assumptions!$E$22 -> 20578.082 | J17: =J13+I13*Assumptions!$E$21+MAX(0,I17-I13)*Assumptions!$E$22 -> 20472.57 | K17: =K13+J13*Assumptions!$E$21+MAX(0,J17-J13)*Assumptions!$E$22 -> 35601.958 | ... AL17: =AL13+AK13*Assumptions!$E$21+MAX(0,AK17-AK13)*Assumptions!$E$22 -> 109362.56
A18: VIP subscribers | C18: =C17*Assumptions!$E$24 -> 219.54545 | D18: =D17*Assumptions!$E$24 -> 173.56364 | E18: =E17*Assumptions!$E$24 -> 417.58227 | F18: =F17*Assumptions!$E$24 -> 249.68355 | G18: =G17*Assumptions!$E$24 -> 254.48705 | H18: =H17*Assumptions!$E$24 -> 485.71586 | I18: =I17*Assumptions!$E$24 -> 308.67123 | J18: =J17*Assumptions!$E$24 -> 307.08854 | ... AL18: =AL17*Assumptions!$E$24 -> 1640.4384
A19: In-app spenders | C19: =C17*Assumptions!$E$26 -> 365.90909 | D19: =D17*Assumptions!$E$26 -> 289.27273 | E19: =E17*Assumptions!$E$26 -> 695.97045 | F19: =F17*Assumptions!$E$26 -> 416.13925 | G19: =G17*Assumptions!$E$26 -> 424.14508 | H19: =H17*Assumptions!$E$26 -> 809.52643 | I19: =I17*Assumptions!$E$26 -> 514.45205 | J19: =J17*Assumptions!$E$26 -> 511.81424 | ... AL19: =AL17*Assumptions!$E$26 -> 2734.064
A20: Active artist partnerships | C20: =SUMPRODUCT(($C$3:C$3>C$3-Assumptions!$E$17)*($C$11:C11)) -> 0 | D20: =SUMPRODUCT(($C$3:D$3>D$3-Assumptions!$E$17)*($C$11:D11)) -> 0 | E20: =SUMPRODUCT(($C$3:E$3>E$3-Assumptions!$E$17)*($C$11:E11)) -> 1 | F20: =SUMPRODUCT(($C$3:F$3>F$3-Assumptions!$E$17)*($C$11:F11)) -> 1 | G20: =SUMPRODUCT(($C$3:G$3>G$3-Assumptions!$E$17)*($C$11:G11)) -> 1 | H20: =SUMPRODUCT(($C$3:H$3>H$3-Assumptions!$E$17)*($C$11:H11)) -> 2 | I20: =SUMPRODUCT(($C$3:I$3>I$3-Assumptions!$E$17)*($C$11:I11)) -> 2 | J20: =SUMPRODUCT(($C$3:J$3>J$3-Assumptions!$E$17)*($C$11:J11)) -> 2 | ... AL20: =SUMPRODUCT(($C$3:AL$3>AL$3-Assumptions!$E$17)*($C$11:AL11)) -> 4
A21: REVENUE (gross)
A22: VIP subscriptions | C22: =C18*Assumptions!$E$25 -> 878.18182 | D22: =D18*Assumptions!$E$25 -> 694.25455 | E22: =E18*Assumptions!$E$25 -> 1670.3291 | F22: =F18*Assumptions!$E$25 -> 998.7342 | G22: =G18*Assumptions!$E$25 -> 1017.9482 | H22: =H18*Assumptions!$E$25 -> 1942.8634 | I22: =I18*Assumptions!$E$25 -> 1234.6849 | J22: =J18*Assumptions!$E$25 -> 1228.3542 | ... AL22: =AL18*Assumptions!$E$25 -> 6561.7536
A23: In-app purchases (Gold, AI songs, cash, artist packs) | C23: =C19*Assumptions!$E$27 -> 2927.2727 | D23: =D19*Assumptions!$E$27 -> 2314.1818 | E23: =E19*Assumptions!$E$27 -> 5567.7636 | F23: =F19*Assumptions!$E$27 -> 3329.114 | G23: =G19*Assumptions!$E$27 -> 3393.1606 | H23: =H19*Assumptions!$E$27 -> 6476.2114 | I23: =I19*Assumptions!$E$27 -> 4115.6164 | J23: =J19*Assumptions!$E$27 -> 4094.5139 | ... AL23: =AL19*Assumptions!$E$27 -> 21872.512
A24: Merch sales | C24: =C17*Assumptions!$E$29*Assumptions!$E$30 -> 1280.6818 | D24: =D17*Assumptions!$E$29*Assumptions!$E$30 -> 1012.4545 | E24: =E17*Assumptions!$E$29*Assumptions!$E$30 -> 2435.8966 | F24: =F17*Assumptions!$E$29*Assumptions!$E$30 -> 1456.4874 | G24: =G17*Assumptions!$E$29*Assumptions!$E$30 -> 1484.5078 | H24: =H17*Assumptions!$E$29*Assumptions!$E$30 -> 2833.3425 | I24: =I17*Assumptions!$E$29*Assumptions!$E$30 -> 1800.5822 | J24: =J17*Assumptions!$E$29*Assumptions!$E$30 -> 1791.3498 | ... AL24: =AL17*Assumptions!$E$29*Assumptions!$E$30 -> 9569.2241
A25: Brand & venue sponsorships | C25: =IF(C$3>=7,Assumptions!$E$31*1.05^(C$3-7),0) -> 0 | D25: =IF(D$3>=7,Assumptions!$E$31*1.05^(D$3-7),0) -> 0 | E25: =IF(E$3>=7,Assumptions!$E$31*1.05^(E$3-7),0) -> 0 | F25: =IF(F$3>=7,Assumptions!$E$31*1.05^(F$3-7),0) -> 0 | G25: =IF(G$3>=7,Assumptions!$E$31*1.05^(G$3-7),0) -> 0 | H25: =IF(H$3>=7,Assumptions!$E$31*1.05^(H$3-7),0) -> 0 | I25: =IF(I$3>=7,Assumptions!$E$31*1.05^(I$3-7),0) -> 5000 | J25: =IF(J$3>=7,Assumptions!$E$31*1.05^(J$3-7),0) -> 5250 | ... AL25: =IF(AL$3>=7,Assumptions!$E$31*1.05^(AL$3-7),0) -> 20580.678
A26: Total revenue | C26: =SUM(C22:C25) -> 5086.1364 | D26: =SUM(D22:D25) -> 4020.8909 | E26: =SUM(E22:E25) -> 9673.9893 | F26: =SUM(F22:F25) -> 5784.3356 | G26: =SUM(G22:G25) -> 5895.6166 | H26: =SUM(H22:H25) -> 11252.417 | I26: =SUM(I22:I25) -> 12150.883 | J26: =SUM(J22:J25) -> 12364.218 | ... AL26: =SUM(AL22:AL25) -> 58584.168
A27: COST OF REVENUE
A28: App Store / Google Play fees | C28: =(C22+C23)*Assumptions!$E$33 -> 570.81818 | D28: =(D22+D23)*Assumptions!$E$33 -> 451.26545 | E28: =(E22+E23)*Assumptions!$E$33 -> 1085.7139 | F28: =(F22+F23)*Assumptions!$E$33 -> 649.17723 | G28: =(G22+G23)*Assumptions!$E$33 -> 661.66632 | H28: =(H22+H23)*Assumptions!$E$33 -> 1262.8612 | I28: =(I22+I23)*Assumptions!$E$33 -> 802.5452 | J28: =(J22+J23)*Assumptions!$E$33 -> 798.43022 | ... AL28: =(AL22+AL23)*Assumptions!$E$33 -> 4265.1399
A29: RevenueCat | C29: =MAX(0,C22+C23-Assumptions!$E$34)*Assumptions!$E$35 -> 13.054545 | D29: =MAX(0,D22+D23-Assumptions!$E$34)*Assumptions!$E$35 -> 5.0843636 | E29: =MAX(0,E22+E23-Assumptions!$E$34)*Assumptions!$E$35 -> 47.380927 | F29: =MAX(0,F22+F23-Assumptions!$E$34)*Assumptions!$E$35 -> 18.278482 | G29: =MAX(0,G22+G23-Assumptions!$E$34)*Assumptions!$E$35 -> 19.111088 | H29: =MAX(0,H22+H23-Assumptions!$E$34)*Assumptions!$E$35 -> 59.190749 | I29: =MAX(0,I22+I23-Assumptions!$E$34)*Assumptions!$E$35 -> 28.503013 | J29: =MAX(0,J22+J23-Assumptions!$E$34)*Assumptions!$E$35 -> 28.228681 | ... AL29: =MAX(0,AL22+AL23-Assumptions!$E$34)*Assumptions!$E$35 -> 259.34266
A30: Artist revenue share | C30: =C23*(1-Assumptions!$E$33)*Assumptions!$E$28*Assumptions!$E$36 -> 223.93636 | D30: =D23*(1-Assumptions!$E$33)*Assumptions!$E$28*Assumptions!$E$36 -> 177.03491 | E30: =E23*(1-Assumptions!$E$33)*Assumptions!$E$28*Assumptions!$E$36 -> 425.93392 | F30: =F23*(1-Assumptions!$E$33)*Assumptions!$E$28*Assumptions!$E$36 -> 254.67722 | G30: =G23*(1-Assumptions!$E$33)*Assumptions!$E$28*Assumptions!$E$36 -> 259.57679 | H30: =H23*(1-Assumptions!$E$33)*Assumptions!$E$28*Assumptions!$E$36 -> 495.43018 | I30: =I23*(1-Assumptions!$E$33)*Assumptions!$E$28*Assumptions!$E$36 -> 314.84465 | J30: =J23*(1-Assumptions!$E$33)*Assumptions!$E$28*Assumptions!$E$36 -> 313.23032 | ... AL30: =AL23*(1-Assumptions!$E$33)*Assumptions!$E$28*Assumptions!$E$36 -> 1673.2472
A31: Music licensing | C31: =C20*Assumptions!$E$37 -> 0 | D31: =D20*Assumptions!$E$37 -> 0 | E31: =E20*Assumptions!$E$37 -> 1000 | F31: =F20*Assumptions!$E$37 -> 1000 | G31: =G20*Assumptions!$E$37 -> 1000 | H31: =H20*Assumptions!$E$37 -> 2000 | I31: =I20*Assumptions!$E$37 -> 2000 | J31: =J20*Assumptions!$E$37 -> 2000 | ... AL31: =AL20*Assumptions!$E$37 -> 4000
A32: Tour ticket & VIP giveaways | C32: =C20*Assumptions!$E$38 -> 0 | D32: =D20*Assumptions!$E$38 -> 0 | E32: =E20*Assumptions!$E$38 -> 1500 | F32: =F20*Assumptions!$E$38 -> 1500 | G32: =G20*Assumptions!$E$38 -> 1500 | H32: =H20*Assumptions!$E$38 -> 3000 | I32: =I20*Assumptions!$E$38 -> 3000 | J32: =J20*Assumptions!$E$38 -> 3000 | ... AL32: =AL20*Assumptions!$E$38 -> 6000
A33: Player prizes (rewards store) | C33: =Assumptions!$E$39+C17*Assumptions!$E$40 -> 2731.8182 | D33: =Assumptions!$E$39+D17*Assumptions!$E$40 -> 2578.5455 | E33: =Assumptions!$E$39+E17*Assumptions!$E$40 -> 3391.9409 | F33: =Assumptions!$E$39+F17*Assumptions!$E$40 -> 2832.2785 | G33: =Assumptions!$E$39+G17*Assumptions!$E$40 -> 2848.2902 | H33: =Assumptions!$E$39+H17*Assumptions!$E$40 -> 3619.0529 | I33: =Assumptions!$E$39+I17*Assumptions!$E$40 -> 3028.9041 | J33: =Assumptions!$E$39+J17*Assumptions!$E$40 -> 3023.6285 | ... AL33: =Assumptions!$E$39+AL17*Assumptions!$E$40 -> 7468.128
A34: Merch cost of goods + fulfillment | C34: =C24*Assumptions!$E$41 -> 704.375 | D34: =D24*Assumptions!$E$41 -> 556.85 | E34: =E24*Assumptions!$E$41 -> 1339.7431 | F34: =F24*Assumptions!$E$41 -> 801.06806 | G34: =G24*Assumptions!$E$41 -> 816.47927 | H34: =H24*Assumptions!$E$41 -> 1558.3384 | I34: =I24*Assumptions!$E$41 -> 990.32019 | J34: =J24*Assumptions!$E$41 -> 985.24241 | ... AL34: =AL24*Assumptions!$E$41 -> 5263.0732
A35: AI (songs, voice, press) | C35: =C17*Assumptions!$E$42 -> 585.45455 | D35: =D17*Assumptions!$E$42 -> 462.83636 | E35: =E17*Assumptions!$E$42 -> 1113.5527 | F35: =F17*Assumptions!$E$42 -> 665.8228 | G35: =G17*Assumptions!$E$42 -> 678.63212 | H35: =H17*Assumptions!$E$42 -> 1295.2423 | I35: =I17*Assumptions!$E$42 -> 823.12328 | J35: =J17*Assumptions!$E$42 -> 818.90279 | ... AL35: =AL17*Assumptions!$E$42 -> 4374.5024
A36: Hosting & infrastructure | C36: =Assumptions!$E$43+C17*Assumptions!$E$44 -> 367.09091 | D36: =Assumptions!$E$43+D17*Assumptions!$E$44 -> 342.56727 | E36: =Assumptions!$E$43+E17*Assumptions!$E$44 -> 472.71055 | F36: =Assumptions!$E$43+F17*Assumptions!$E$44 -> 383.16456 | G36: =Assumptions!$E$43+G17*Assumptions!$E$44 -> 385.72642 | H36: =Assumptions!$E$43+H17*Assumptions!$E$44 -> 509.04846 | I36: =Assumptions!$E$43+I17*Assumptions!$E$44 -> 414.62466 | J36: =Assumptions!$E$43+J17*Assumptions!$E$44 -> 413.78056 | ... AL36: =Assumptions!$E$43+AL17*Assumptions!$E$44 -> 1124.9005
A37: Total cost of revenue | C37: =SUM(C28:C36) -> 5196.5477 | D37: =SUM(D28:D36) -> 4574.1838 | E37: =SUM(E28:E36) -> 10376.976 | F37: =SUM(F28:F36) -> 8104.4668 | G37: =SUM(G28:G36) -> 8169.4822 | H37: =SUM(H28:H36) -> 13799.164 | I37: =SUM(I28:I36) -> 11402.865 | J37: =SUM(J28:J36) -> 11381.443 | ... AL37: =SUM(AL28:AL36) -> 34428.334
A38: Gross profit | C38: =C26-C37 -> -110.41136 | D38: =D26-D37 -> -553.29291 | E38: =E26-E37 -> -702.98674 | F38: =F26-F37 -> -2320.1313 | G38: =G26-G37 -> -2273.8656 | H38: =H26-H37 -> -2546.7468 | I38: =I26-I37 -> 748.01839 | J38: =J26-J37 -> 982.7745 | ... AL38: =AL26-AL37 -> 24155.834
A39: Gross margin | C39: =IFERROR(C38/C26,0) -> -0.021708298 | D39: =IFERROR(D38/D26,0) -> -0.13760456 | E39: =IFERROR(E38/E26,0) -> -0.07266772 | F39: =IFERROR(F38/F26,0) -> -0.40110593 | G39: =IFERROR(G38/G26,0) -> -0.3856875 | H39: =IFERROR(H38/H26,0) -> -0.22632886 | I39: =IFERROR(I38/I26,0) -> 0.061560823 | J39: =IFERROR(J38/J26,0) -> 0.079485375 | ... AL39: =IFERROR(AL38/AL26,0) -> 0.412327
A40: OPERATING EXPENSES
...
